Workbook

Sheet Resumo
A1: BetIntel AI - Dataset de treino das ultimas 5 Copas concluidas
A2: Escopo | B2: Copas do Mundo masculinas FIFA 2006, 2010, 2014, 2018 e 2022.
A3: Uso recomendado | B3: Treino/evaluacao educacional. Analise baseada em dados historicos. Nao garante resultado.
A4: Google | B4: Nao foi usado como fonte de treino; o arquivo usa fontes CSV reproduziveis e URLs auditaveis.
A5: Odds | B5: Odds reais foram ignoradas e nao constam nas abas de treino.
A7: Indicador | B7: Valor
A8: Partidas | B8: =SUM(Por_Edicao!B2:B6) -> 320
A9: Partidas com escanteios | B9: =SUM(Por_Edicao!H2:H6) -> 256
A10: Partidas sem escanteios por partida | B10: =B8-B9 -> 64
A11: Gols | B11: =SUM(Por_Edicao!C2:C6) -> 804
A12: TotalCards modelo | B12: =SUM(Por_Edicao!M2:M6) -> 1272
A13: Fonte principal resultados/cartoes | B13: https://github.com/jfjelstul/worldcup
A14: Fonte principal escanteios | B14: https://footystats.org/world-cup

Sheet Partidas
A1: tournament_year | B1: tournament_name | C1: match_id | D1: stage | E1: group_name | F1: match_date | G1: match_time | H1: home_team | I1: away_team | J1: home_goals | K1: away_goals | L1: score | M1: result_1x2 | N1: official_result | O1: winner_team | P1: winner_basis | Q1: extra_time | R1: penalty_shootout | S1: penalty_score | T1: home_corners | U1: away_corners | V1: total_corners | W1: corners_status | X1: home_yellow_cards | Y1: away_yellow_cards | Z1: total_yellow_cards | AA1: home_straight_red_cards | AB1: away_straight_red_cards | AC1: total_straight_red_cards | AD1: home_second_yellow_cards | AE1: away_second_yellow_cards | AF1: total_second_yellow_cards | AG1: home_red_card_sendoffs | AH1: away_red_card_sendoffs | AI1: total_red_card_sendoffs | AJ1: total_cards_model | AK1: cards_status | AL1: home_shots | AM1: away_shots | AN1: home_shots_on_target | AO1: away_shots_on_target | AP1: home_possession | AQ1: away_possession | AR1: stadium | AS1: city | AT1: country | AU1: results_source | AV1: cards_source | AW1: corners_source | AX1: notes
A2: 2006 | B2: 2006 FIFA Men's World Cup | C2: M-2006-01 | D2: group stage | E2: Group A | F2: 38877 | G2: 18:00 | H2: Germany | I2: Costa Rica | J2: 4 | K2: 2 | L2: 4–2 | M2: H | N2: Germany | O2: Germany | P2: score | Q2: FALSE | R2: FALSE | S2: 0-0 | W2: dados_insuficientes | X2: 0 | Y2: 1 | Z2: 1 | AA2: 0 | AB2: 0 | AC2: 0 | AD2: 0 | AE2: 0 | AF2: 0 | AG2: 0 | AH2: 0 | AI2: 0 | AJ2: 1 | AK2: ok | AL2: -1 | AM2: -1 | AN2: -1 | AO2: -1 | AP2: -1 | AQ2: -1 | AR2: Allianz Arena | AS2: Munich | AT2: Germany | AU2: https://raw.githubusercontent.com/jfjelstul/worldcup/master/data-csv/matches.csv | AV2: https://raw.githubusercontent.com/jfjelstul/worldcup/master/data-csv/bookings.csv | AW2: https://footystats.org/c-dl.php?comp=1419&type=matches | AX2: Escanteios por partida indisponiveis no CSV FootyStats desta edicao; nao preencher com estimativa.
A3: 2006 | B3: 2006 FIFA Men's World Cup | C3: M-2006-02 | D3: group stage | E3: Group A | F3: 38877 | G3: 21:00 | H3: Poland | I3: Ecuador | J3: 0 | K3: 2 | L3: 0–2 | M3: A | N3: Ecuador | O3: Ecuador | P3: score | Q3: FALSE | R3: FALSE | S3: 0-0 | W3: dados_insuficientes | X3: 1 | Y3: 2 | Z3: 3 | AA3: 0 | AB3: 0 | AC3: 0 | AD3: 0 | AE3: 0 | AF3: 0 | AG3: 0 | AH3: 0 | AI3: 0 | AJ3: 3 | AK3: ok | AL3: -1 | AM3: -1 | AN3: -1 | AO3: -1 | AP3: -1 | AQ3: -1 | AR3: Arena AufShalke | AS3: Gelsenkirchen | AT3: Germany | AU3: https://raw.githubusercontent.com/jfjelstul/worldcup/master/data-csv/matches.csv | AV3: https://raw.githubusercontent.com/jfjelstul/worldcup/master/data-csv/bookings.csv | AW3: https://footystats.org/c-dl.php?comp=1419&type=matches | AX3: Escanteios por partida indisponiveis no CSV FootyStats desta edicao; nao preencher com estimativa.
A4: 2006 | B4: 2006 FIFA Men's World Cup | C4: M-2006-03 | D4: group stage | E4: Group B | F4: 38878 | G4: 15:00 | H4: England | I4: Paraguay | J4: 1 | K4: 0 | L4: 1–0 | M4: H | N4: England | O4: England | P4: score | Q4: FALSE | R4: FALSE | S4: 0-0 | W4: dados_insuficientes | X4: 2 | Y4: 1 | Z4: 3 | AA4: 0 | AB4: 0 | AC4: 0 | AD4: 0 | AE4: 0 | AF4: 0 | AG4: 0 | AH4: 0 | AI4: 0 | AJ4: 3 | AK4: ok | AL4: -1 | AM4: -1 | AN4: -1 | AO4: -1 | AP4: -1 | AQ4: -1 | AR4: Waldstadion | AS4: Frankfurt | AT4: Germany | AU4: https://raw.githubusercontent.com/jfjelstul/worldcup/master/data-csv/matches.csv | AV4: https://raw.githubusercontent.com/jfjelstul/worldcup/master/data-csv/bookings.csv | AW4: https://footystats.org/c-dl.php?comp=1419&type=matches | AX4: Escanteios por partida indisponiveis no CSV FootyStats desta edicao; nao preencher com estimativa.
A5: 2006 | B5: 2006 FIFA Men's World Cup | C5: M-2006-04 | D5: group stage | E5: Group B | F5: 38878 | G5: 18:00 | H5: Trinidad and Tobago | I5: Sweden | J5: 0 | K5: 0 | L5: 0–0 | M5: D | N5: Draw | P5: draw_no_winner | Q5: FALSE | R5: FALSE | S5: 0-0 | W5: dados_insuficientes | X5: 2 | Y5: 1 | Z5: 3 | AA5: 0 | AB5: 0 | AC5: 0 | AD5: 1 | AE5: 0 | AF5: 1 | AG5: 1 | AH5: 0 | AI5: 1 | AJ5: 4 | AK5: ok | AL5: -1 | AM5: -1 | AN5: -1 | AO5: -1 | AP5: -1 | AQ5: -1 | AR5: Westfalenstadion | AS5: Dortmund | AT5: Germany | AU5: https://raw.githubusercontent.com/jfjelstul/worldcup/master/data-csv/matches.csv | AV5: https://raw.githubusercontent.com/jfjelstul/worldcup/master/data-csv/bookings.csv | AW5: https://footystats.org/c-dl.php?comp=1419&type=matches | AX5: Escanteios por partida indisponiveis no CSV FootyStats desta edicao; nao preencher com estimativa.
A6: 2006 | B6: 2006 FIFA Men's World Cup | C6: M-2006-05 | D6: group stage | E6: Group C | F6: 38878 | G6: 21:00 | H6: Argentina | I6: Ivory Coast | J6: 2 | K6: 1 | L6: 2–1 | M6: H | N6: Argentina | O6: Argentina | P6: score | Q6: FALSE | R6: FALSE | S6: 0-0 | W6: dados_insuficientes | X6: 3 | Y6: 2 | Z6: 5 | AA6: 0 | AB6: 0 | AC6: 0 | AD6: 0 | AE6: 0 | AF6: 0 | AG6: 0 | AH6: 0 | AI6: 0 | AJ6: 5 | AK6: ok | AL6: -1 | AM6: -1 | AN6: -1 | AO6: -1 | AP6: -1 | AQ6: -1 | AR6: Volksparkstadion | AS6: Hamburg | AT6: Germany | AU6: https://raw.githubusercontent.com/jfjelstul/worldcup/master/data-csv/matches.csv | AV6: https://raw.githubusercontent.com/jfjelstul/worldcup/master/data-csv/bookings.csv | AW6: https://footystats.org/c-dl.php?comp=1419&type=matches | AX6: Escanteios por partida indisponiveis no CSV FootyStats desta edicao; nao preencher com estimativa.
A7: 2006 | B7: 2006 FIFA Men's World Cup | C7: M-2006-06 | D7: group stage | E7: Group C | F7: 38879 | G7: 15:00 | H7: Serbia and Montenegro | I7: Netherlands | J7: 0 | K7: 1 | L7: 0–1 | M7: A | N7: Netherlands | O7: Netherlands | P7: score | Q7: FALSE | R7: FALSE | S7: 0-0 | W7: dados_insuficientes | X7: 4 | Y7: 2 | Z7: 6 | AA7: 0 | AB7: 0 | AC7: 0 | AD7: 0 | AE7: 0 | AF7: 0 | AG7: 0 | AH7: 0 | AI7: 0 | AJ7: 6 | AK7: ok | AL7: -1 | AM7: -1 | AN7: -1 | AO7: -1 | AP7: -1 | AQ7: -1 | AR7: Zentralstadion | AS7: Leipzig | AT7: Germany | AU7: https://raw.githubusercontent.com/jfjelstul/worldcup/master/data-csv/matches.csv | AV7: https://raw.githubusercontent.com/jfjelstul/worldcup/master/data-csv/bookings.csv | AW7: https://footystats.org/c-dl.php?comp=1419&type=matches | AX7: Escanteios por partida indisponiveis no CSV FootyStats desta edicao; nao preencher com estimativa.
A8: 2006 | B8: 2006 FIFA Men's World Cup | C8: M-2006-07 | D8: group stage | E8: Group D | F8: 38879 | G8: 18:00 | H8: Mexico | I8: Iran | J8: 3 | K8: 1 | L8: 3–1 | M8: H | N8: Mexico | O8: Mexico | P8: score | Q8: FALSE | R8: FALSE | S8: 0-0 | W8: dados_insuficientes | X8: 2 | Y8: 1 | Z8: 3 | AA8: 0 | AB8: 0 | AC8: 0 | AD8: 0 | AE8: 0 | AF8: 0 | AG8: 0 | AH8: 0 | AI8: 0 | AJ8: 3 | AK8: ok | AL8: -1 | AM8: -1 | AN8: -1 | AO8: -1 | AP8: -1 | AQ8: -1 | AR8: Frankenstadion | AS8: Nuremberg | AT8: Germany | AU8: https://raw.githubusercontent.com/jfjelstul/worldcup/master/data-csv/matches.csv | AV8: https://raw.githubusercontent.com/jfjelstul/worldcup/master/data-csv/bookings.csv | AW8: https://footystats.org/c-dl.php?comp=1419&type=matches | AX8: Escanteios por partida indisponiveis no CSV FootyStats desta edicao; nao preencher com estimativa.
A9: 2006 | B9: 2006 FIFA Men's World Cup | C9: M-2006-08 | D9: group stage | E9: Group D | F9: 38879 | G9: 21:00 | H9: Angola | I9: Portugal | J9: 0 | K9: 1 | L9: 0–1 | M9: A | N9: Portugal | O9: Portugal | P9: score | Q9: FALSE | R9: FALSE | S9: 0-0 | W9: dados_insuficientes | X9: 3 | Y9: 2 | Z9: 5 | AA9: 0 | AB9: 0 | AC9: 0 | AD9: 0 | AE9: 0 | AF9: 0 | AG9: 0 | AH9: 0 | AI9: 0 | AJ9: 5 | AK9: ok | AL9: -1 | AM9: -1 | AN9: -1 | AO9: -1 | AP9: -1 | AQ9: -1 | AR9: RheinEnergieStadion | AS9: Cologne | AT9: Germany | AU9: https://raw.githubusercontent.com/jfjelstul/worldcup/master/data-csv/matches.csv | AV9: https://raw.githubusercontent.com/jfjelstul/worldcup/master/data-csv/bookings.csv | AW9: https://footystats.org/c-dl.php?comp=1419&type=matches | AX9: Escanteios por partida indisponiveis no CSV FootyStats desta edicao; nao preencher com estimativa.
A10: 2006 | B10: 2006 FIFA Men's World Cup | C10: M-2006-09 | D10: group stage | E10: Group F | F10: 38880 | G10: 15:00 | H10: Australia | I10: Japan | J10: 3 | K10: 1 | L10: 3–1 | M10: H | N10: Australia | O10: Australia | P10: score | Q10: FALSE | R10: FALSE | S10: 0-0 | W10: dados_insuficientes | X10: 4 | Y10: 3 | Z10: 7 | AA10: 0 | AB10: 0 | AC10: 0 | AD10: 0 | AE10: 0 | AF10: 0 | AG10: 0 | AH10: 0 | AI10: 0 | AJ10: 7 | AK10: ok | AL10: -1 | AM10: -1 | AN10: -1 | AO10: -1 | AP10: -1 | AQ10: -1 | AR10: Fritz-Walter-Stadion | AS10: Kaiserslautern | AT10: Germany | AU10: https://raw.githubusercontent.com/jfjelstul/worldcup/master/data-csv/matches.csv | AV10: https://raw.githubusercontent.com/jfjelstul/worldcup/master/data-csv/bookings.csv | AW10: https://footystats.org/c-dl.php?comp=1419&type=matches | AX10: Escanteios por partida indisponiveis no CSV FootyStats desta edicao; nao preencher com estimativa.
A11: 2006 | B11: 2006 FIFA Men's World Cup | C11: M-2006-10 | D11: group stage | E11: Group E | F11: 38880 | G11: 18:00 | H11: United States | I11: Czech Republic | J11: 0 | K11: 3 | L11: 0–3 | M11: A | N11: Czech Republic | O11: Czech Republic | P11: score | Q11: FALSE | R11: FALSE | S11: 0-0 | W11: dados_insuficientes | X11: 2 | Y11: 4 | Z11: 6 | AA11: 0 | AB11: 0 | AC11: 0 | AD11: 0 | AE11: 0 | AF11: 0 | AG11: 0 | AH11: 0 | AI11: 0 | AJ11: 6 | AK11: ok | AL11: -1 | AM11: -1 | AN11: -1 | AO11: -1 | AP11: -1 | AQ11: -1 | AR11: Arena AufShalke | AS11: Gelsenkirchen | AT11: Germany | AU11: https://raw.githubusercontent.com/jfjelstul/worldcup/master/data-csv/matches.csv | AV11: https://raw.githubusercontent.com/jfjelstul/worldcup/master/data-csv/bookings.csv | AW11: https://footystats.org/c-dl.php?comp=1419&type=matches | AX11: Escanteios por partida indisponiveis no CSV FootyStats desta edicao; nao preencher com estimativa.
A12: 2006 | B12: 2006 FIFA Men's World Cup | C12: M-2006-11 | D12: group stage | E12: Group E | F12: 38880 | G12: 21:00 | H12: Italy | I12: Ghana | J12: 2 | K12: 0 | L12: 2–0 | M12: H | N12: Italy | O12: Italy | P12: score | Q12: FALSE | R12: FALSE | S12: 0-0 | W12: dados_insuficientes | X12: 3 | Y12: 2 | Z12: 5 | AA12: 0 | AB12: 0 | AC12: 0 | AD12: 0 | AE12: 0 | AF12: 0 | AG12: 0 | AH12: 0 | AI12: 0 | AJ12: 5 | AK12: ok | AL12: -1 | AM12: -1 | AN12: -1 | AO12: -1 | AP12: -1 | AQ12: -1 | AR12: Niedersachsenstadion | AS12: Hanover | AT12: Germany | AU12: https://raw.githubusercontent.com/jfjelstul/worldcup/master/data-csv/matches.csv | AV12: https://raw.githubusercontent.com/jfjelstul/worldcup/master/data-csv/bookings.csv | AW12: https://footystats.org/c-dl.php?comp=1419&type=matches | AX12: Escanteios por partida indisponiveis no CSV FootyStats desta edicao; nao preencher com estimativa.
A13: 2006 | B13: 2006 FIFA Men's World Cup | C13: M-2006-12 | D13: group stage | E13: Group G | F13: 38881 | G13: 15:00 | H13: South Korea | I13: Togo | J13: 2 | K13: 1 | L13: 2–1 | M13: H | N13: South Korea | O13: South Korea | P13: score | Q13: FALSE | R13: FALSE | S13: 0-0 | W13: dados_insuficientes | X13: 2 | Y13: 3 | Z13: 5 | AA13: 0 | AB13: 0 | AC13: 0 | AD13: 0 | AE13: 1 | AF13: 1 | AG13: 0 | AH13: 1 | AI13: 1 | AJ13: 6 | AK13: ok | AL13: -1 | AM13: -1 | AN13: -1 | AO13: -1 | AP13: -1 | AQ13: -1 | AR13: Waldstadion | AS13: Frankfurt | AT13: Germany | AU13: https://raw.githubusercontent.com/jfjelstul/worldcup/master/data-csv/matches.csv | AV13: https://raw.githubusercontent.com/jfjelstul/worldcup/master/data-csv/bookings.csv | AW13: https://footystats.org/c-dl.php?comp=1419&type=matches | AX13: Escanteios por partida indisponiveis no CSV FootyStats desta edicao; nao preencher com estimativa.
A14: 2006 | B14: 2006 FIFA Men's World Cup | C14: M-2006-13 | D14: group stage | E14: Group G | F14: 38881 | G14: 18:00 | H14: France | I14: Switzerland | J14: 0 | K14: 0 | L14: 0–0 | M14: D | N14: Draw | P14: draw_no_winner | Q14: FALSE | R14: FALSE | S14: 0-0 | W14: dados_insuficientes | X14: 3 | Y14: 5 | Z14: 8 | AA14: 0 | AB14: 0 | AC14: 0 | AD14: 0 | AE14: 0 | AF14: 0 | AG14: 0 | AH14: 0 | AI14: 0 | AJ14: 8 | AK14: ok | AL14: -1 | AM14: -1 | AN14: -1 | AO14: -1 | AP14: -1 | AQ14: -1 | AR14: Neckarstadion | AS14: Stuttgart | AT14: Germany | AU14: https://raw.githubusercontent.com/jfjelstul/worldcup/master/data-csv/matches.csv | AV14: https://raw.githubusercontent.com/jfjelstul/worldcup/master/data-csv/bookings.csv | AW14: https://footystats.org/c-dl.php?comp=1419&type=matches | AX14: Escanteios por partida indisponiveis no CSV FootyStats desta edicao; nao preencher com estimativa.
A15: 2006 | B15: 2006 FIFA Men's World Cup | C15: M-2006-14 | D15: group stage | E15: Group F | F15: 38881 | G15: 21:00 | H15: Brazil | I15: Croatia | J15: 1 | K15: 0 | L15: 1–0 | M15: H | N15: Brazil | O15: Brazil | P15: score | Q15: FALSE | R15: FALSE | S15: 0-0 | W15: dados_insuficientes | X15: 1 | Y15: 3 | Z15: 4 | AA15: 0 | AB15: 0 | AC15: 0 | AD15: 0 | AE15: 0 | AF15: 0 | AG15: 0 | AH15: 0 | AI15: 0 | AJ15: 4 | AK15: ok | AL15: -1 | AM15: -1 | AN15: -1 | AO15: -1 | AP15: -1 | AQ15: -1 | AR15: Olympiastadion | AS15: Berlin | AT15: Germany | AU15: https://raw.githubusercontent.com/jfjelstul/worldcup/master/data-csv/matches.csv | AV15: https://raw.githubusercontent.com/jfjelstul/worldcup/master/data-csv/bookings.csv | AW15: https://footystats.org/c-dl.php?comp=1419&type=matches | AX15: Escanteios por partida indisponiveis no CSV FootyStats desta edicao; nao preencher com estimativa.
A16: 2006 | B16: 2006 FIFA Men's World Cup | C16: M-2006-15 | D16: group stage | E16: Group H | F16: 38882 | G16: 15:00 | H16: Spain | I16: Ukraine | J16: 4 | K16: 0 | L16: 4–0 | M16: H | N16: Spain | O16: Spain | P16: score | Q16: FALSE | R16: FALSE | S16: 0-0 | W16: dados_insuficientes | X16: 0 | Y16: 2 | Z16: 2 | AA16: 0 | AB16: 1 | AC16: 1 | AD16: 0 | AE16: 0 | AF16: 0 | AG16: 0 | AH16: 1 | AI16: 1 | AJ16: 3 | AK16: ok | AL16: -1 | AM16: -1 | AN16: -1 | AO16: -1 | AP16: -1 | AQ16: -1 | AR16: Zentralstadion | AS16: Leipzig | AT16: Germany | AU16: https://raw.githubusercontent.com/jfjelstul/worldcup/master/data-csv/matches.csv | AV16: https://raw.githubusercontent.com/jfjelstul/worldcup/master/data-csv/bookings.csv | AW16: https://footystats.org/c-dl.php?comp=1419&type=matches | AX16: Escanteios por partida indisponiveis no CSV FootyStats desta edicao; nao preencher com estimativa.
A17: 2006 | B17: 2006 FIFA Men's World Cup | C17: M-2006-16 | D17: group stage | E17: Group H | F17: 38882 | G17: 18:00 | H17: Tunisia | I17: Saudi Arabia | J17: 2 | K17: 2 | L17: 2–2 | M17: D | N17: Draw | P17: draw_no_winner | Q17: FALSE | R17: FALSE | S17: 0-0 | W17: dados_insuficientes | X17: 4 | Y17: 0 | Z17: 4 | AA17: 0 | AB17: 0 | AC17: 0 | AD17: 0 | AE17: 0 | AF17: 0 | AG17: 0 | AH17: 0 | AI17: 0 | AJ17: 4 | AK17: ok | AL17: -1 | AM17: -1 | AN17: -1 | AO17: -1 | AP17: -1 | AQ17: -1 | AR17: Allianz Arena | AS17: Munich | AT17: Germany | AU17: https://raw.githubusercontent.com/jfjelstul/worldcup/master/data-csv/matches.csv | AV17: https://raw.githubusercontent.com/jfjelstul/worldcup/master/data-csv/bookings.csv | AW17: https://footystats.org/c-dl.php?comp=1419&type=matches | AX17: Escanteios por partida indisponiveis no CSV FootyStats desta edicao; nao preencher com estimativa.
A18: 2006 | B18: 2006 FIFA Men's World Cup | C18: M-2006-17 | D18: group stage | E18: Group A | F18: 38882 | G18: 21:00 | H18: Germany | I18: Poland | J18: 1 | K18: 0 | L18: 1–0 | M18: H | N18: Germany | O18: Germany | P18: score | Q18: FALSE | R18: FALSE | S18: 0-0 | W18: dados_insuficientes | X18: 3 | Y18: 3 | Z18: 6 | AA18: 0 | AB18: 0 | AC18: 0 | AD18: 0 | AE18: 1 | AF18: 1 | AG18: 0 | AH18: 1 | AI18: 1 | AJ18: 7 | AK18: ok | AL18: -1 | AM18: -1 | AN18: -1 | AO18: -1 | AP18: -1 | AQ18: -1 | AR18: Westfalenstadion | AS18: Dortmund | AT18: Germany | AU18: https://raw.githubusercontent.com/jfjelstul/worldcup/master/data-csv/matches.csv | AV18: https://raw.githubusercontent.com/jfjelstul/worldcup/master/data-csv/bookings.csv | AW18: https://footystats.org/c-dl.php?comp=1419&type=matches | AX18: Escanteios por partida indisponiveis no CSV FootyStats desta edicao; nao preencher com estimativa.
A19: 2006 | B19: 2006 FIFA Men's World Cup | C19: M-2006-18 | D19: group stage | E19: Group A | F19: 38883 | G19: 15:00 | H19: Ecuador | I19: Costa Rica | J19: 3 | K19: 0 | L19: 3–0 | M19: H | N19: Ecuador | O19: Ecuador | P19: score | Q19: FALSE | R19: FALSE | S19: 0-0 | W19: dados_insuficientes | X19: 3 | Y19: 2 | Z19: 5 | AA19: 0 | AB19: 0 | AC19: 0 | AD19: 0 | AE19: 0 | AF19: 0 | AG19: 0 | AH19: 0 | AI19: 0 | AJ19: 5 | AK19: ok | AL19: -1 | AM19: -1 | AN19: -1 | AO19: -1 | AP19: -1 | AQ19: -1 | AR19: Volksparkstadion | AS19: Hamburg | AT19: Germany | AU19: https://raw.githubusercontent.com/jfjelstul/worldcup/master/data-csv/matches.csv | AV19: https://raw.githubusercontent.com/jfjelstul/worldcup/master/data-csv/bookings.csv | AW19: https://footystats.org/c-dl.php?comp=1419&type=matches | AX19: Escanteios por partida indisponiveis no CSV FootyStats desta edicao; nao preencher com estimativa.
A20: 2006 | B20: 2006 FIFA Men's World Cup | C20: M-2006-19 | D20: group stage | E20: Group B | F20: 38883 | G20: 18:00 | H20: England | I20: Trinidad and Tobago | J20: 2 | K20: 0 | L20: 2–0 | M20: H | N20: England | O20: England | P20: score | Q20: FALSE | R20: FALSE | S20: 0-0 | W20: dados_insuficientes | X20: 1 | Y20: 5 | Z20: 6 | AA20: 0 | AB20: 0 | AC20: 0 | AD20: 0 | AE20: 0 | AF20: 0 | AG20: 0 | AH20: 0 | AI20: 0 | AJ20: 6 | AK20: ok | AL20: -1 | AM20: -1 | AN20: -1 | AO20: -1 | AP20: -1 | AQ20: -1 | AR20: Frankenstadion | AS20: Nuremberg | AT20: Germany | AU20: https://raw.githubusercontent.com/jfjelstul/worldcup/master/data-csv/matches.csv | AV20: https://raw.githubusercontent.com/jfjelstul/worldcup/master/data-csv/bookings.csv | AW20: https://footystats.org/c-dl.php?comp=1419&type=matches | AX20: Escanteios por partida indisponiveis no CSV FootyStats desta edicao; nao preencher com estimativa.
A21: 2006 | B21: 2006 FIFA Men's World Cup | C21: M-2006-20 | D21: group stage | E21: Group B | F21: 38883 | G21: 21:00 | H21: Sweden | I21: Paraguay | J21: 1 | K21: 0 | L21: 1–0 | M21: H | N21: Sweden | O21: Sweden | P21: score | Q21: FALSE | R21: FALSE | S21: 0-0 | W21: dados_insuficientes | X21: 3 | Y21: 5 | Z21: 8 | AA21: 0 | AB21: 0 | AC21: 0 | AD21: 0 | AE21: 0 | AF21: 0 | AG21: 0 | AH21: 0 | AI21: 0 | AJ21: 8 | AK21: ok | AL21: -1 | AM21: -1 | AN21: -1 | AO21: -1 | AP21: -1 | AQ21: -1 | AR21: Olympiastadion | AS21: Berlin | AT21: Germany | AU21: https://raw.githubusercontent.com/jfjelstul/worldcup/master/data-csv/matches.csv | AV21: https://raw.githubusercontent.com/jfjelstul/worldcup/master/data-csv/bookings.csv | AW21: https://footystats.org/c-dl.php?comp=1419&type=matches | AX21: Escanteios por partida indisponiveis no CSV FootyStats desta edicao; nao preencher com estimativa.
A22: 2006 | B22: 2006 FIFA Men's World Cup | C22: M-2006-21 | D22: group stage | E22: Group C | F22: 38884 | G22: 15:00 | H22: Argentina | I22: Serbia and Montenegro | J22: 6 | K22: 0 | L22: 6–0 | M22: H | N22: Argentina | O22: Argentina | P22: score | Q22: FALSE | R22: FALSE | S22: 0-0 | W22: dados_insuficientes | X22: 1 | Y22: 3 | Z22: 4 | AA22: 0 | AB22: 1 | AC22: 1 | AD22: 0 | AE22: 0 | AF22: 0 | AG22: 0 | AH22: 1 | AI22: 1 | AJ22: 5 | AK22: ok | AL22: -1 | AM22: -1 | AN22: -1 | AO22: -1 | AP22: -1 | AQ22: -1 | AR22: Arena AufShalke | AS22: Gelsenkirchen | AT22: Germany | AU22: https://raw.githubusercontent.com/jfjelstul/worldcup/master/data-csv/matches.csv | AV22: https://raw.githubusercontent.com/jfjelstul/worldcup/master/data-csv/bookings.csv | AW22: https://footystats.org/c-dl.php?comp=1419&type=matches | AX22: Escanteios por partida indisponiveis no CSV FootyStats desta edicao; nao preencher com estimativa.
A23: 2006 | B23: 2006 FIFA Men's World Cup | C23: M-2006-22 | D23: group stage | E23: Group C | F23: 38884 | G23: 18:00 | H23: Netherlands | I23: Ivory Coast | J23: 2 | K23: 1 | L23: 2–1 | M23: H | N23: Netherlands | O23: Netherlands | P23: score | Q23: FALSE | R23: FALSE | S23: 0-0 | W23: dados_insuficientes | X23: 4 | Y23: 3 | Z23: 7 | AA23: 0 | AB23: 0 | AC23: 0 | AD23: 0 | AE23: 0 | AF23: 0 | AG23: 0 | AH23: 0 | AI23: 0 | AJ23: 7 | AK23: ok | AL23: -1 | AM23: -1 | AN23: -1 | AO23: -1 | AP23: -1 | AQ23: -1 | AR23: Neckarstadion | AS23: Stuttgart | AT23: Germany | AU23: https://raw.githubusercontent.com/jfjelstul/worldcup/master/data-csv/matches.csv | AV23: https://raw.githubusercontent.com/jfjelstul/worldcup/master/data-csv/bookings.csv | AW23: https://footystats.org/c-dl.php?comp=1419&type=matches | AX23: Escanteios por partida indisponiveis no CSV FootyStats desta edicao; nao preencher com estimativa.
A24: 2006 | B24: 2006 FIFA Men's World Cup | C24: M-2006-23 | D24: group stage | E24: Group D | F24: 38884 | G24: 21:00 | H24: Mexico | I24: Angola | J24: 0 | K24: 0 | L24: 0–0 | M24: D | N24: Draw | P24: draw_no_winner | Q24: FALSE | R24: FALSE | S24: 0-0 | W24: dados_insuficientes | X24: 1 | Y24: 4 | Z24: 5 | AA24: 0 | AB24: 0 | AC24: 0 | AD24: 0 | AE24: 1 | AF24: 1 | AG24: 0 | AH24: 1 | AI24: 1 | AJ24: 6 | AK24: ok | AL24: -1 | AM24: -1 | AN24: -1 | AO24: -1 | AP24: -1 | AQ24: -1 | AR24: Niedersachsenstadion | AS24: Hanover | AT24: Germany | AU24: https://raw.githubusercontent.com/jfjelstul/worldcup/master/data-csv/matches.csv | AV24: https://raw.githubusercontent.com/jfjelstul/worldcup/master/data-csv/bookings.csv | AW24: https://footystats.org/c-dl.php?comp=1419&type=matches | AX24: Escanteios por partida indisponiveis no CSV FootyStats desta edicao; nao preencher com estimativa.
A25: 2006 | B25: 2006 FIFA Men's World Cup | C25: M-2006-24 | D25: group stage | E25: Group D | F25: 38885 | G25: 15:00 | H25: Portugal | I25: Iran | J25: 2 | K25: 0 | L25: 2–0 | M25: H | N25: Portugal | O25: Portugal | P25: score | Q25: FALSE | R25: FALSE | S25: 0-0 | W25: dados_insuficientes | X25: 3 | Y25: 4 | Z25: 7 | AA25: 0 | AB25: 0 | AC25: 0 | AD25: 0 | AE25: 0 | AF25: 0 | AG25: 0 | AH25: 0 | AI25: 0 | AJ25: 7 | AK25: ok | AL25: -1 | AM25: -1 | AN25: -1 | AO25: -1 | AP25: -1 | AQ25: -1 | AR25: Waldstadion | AS25: Frankfurt | AT25: Germany | AU25: https://raw.githubusercontent.com/jfjelstul/worldcup/master/data-csv/matches.csv | AV25: https://raw.githubusercontent.com/jfjelstul/worldcup/master/data-csv/bookings.csv | AW25: https://footystats.org/c-dl.php?comp=1419&type=matches | AX25: Escanteios por partida indisponiveis no CSV FootyStats desta edicao; nao preencher com estimativa.
A26: 2006 | B26: 2006 FIFA Men's World Cup | C26: M-2006-25 | D26: group stage | E26: Group E | F26: 38885 | G26: 18:00 | H26: Czech Republic | I26: Ghana | J26: 0 | K26: 2 | L26: 0–2 | M26: A | N26: Ghana | O26: Ghana | P26: score | Q26: FALSE | R26: FALSE | S26: 0-0 | W26: dados_insuficientes | X26: 1 | Y26: 6 | Z26: 7 | AA26: 1 | AB26: 0 | AC26: 1 | AD26: 0 | AE26: 0 | AF26: 0 | AG26: 1 | AH26: 0 | AI26: 1 | AJ26: 8 | AK26: ok | AL26: -1 | AM26: -1 | AN26: -1 | AO26: -1 | AP26: -1 | AQ26: -1 | AR26: RheinEnergieStadion | AS26: Cologne | AT26: Germany | AU26: https://raw.githubusercontent.com/jfjelstul/worldcup/master/data-csv/matches.csv | AV26: https://raw.githubusercontent.com/jfjelstul/worldcup/master/data-csv/bookings.csv | AW26: https://footystats.org/c-dl.php?comp=1419&type=matches | AX26: Escanteios por partida indisponiveis no CSV FootyStats desta edicao; nao preencher com estimativa.
A27: 2006 | B27: 2006 FIFA Men's World Cup | C27: M-2006-26 | D27: group stage | E27: Group E | F27: 38885 | G27: 21:00 | H27: Italy | I27: United States | J27: 1 | K27: 1 | L27: 1–1 | M27: D | N27: Draw | P27: draw_no_winner | Q27: FALSE | R27: FALSE | S27: 0-0 | W27: dados_insuficientes | X27: 2 | Y27: 1 | Z27: 3 | AA27: 1 | AB27: 1 | AC27: 2 | AD27: 0 | AE27: 1 | AF27: 1 | AG27: 1 | AH27: 2 | AI27: 3 | AJ27: 6 | AK27: ok | AL27: -1 | AM27: -1 | AN27: -1 | AO27: -1 | AP27: -1 | AQ27: -1 | AR27: Fritz-Walter-Stadion | AS27: Kaiserslautern | AT27: Germany | AU27: https://raw.githubusercontent.com/jfjelstul/worldcup/master/data-csv/matches.csv | AV27: https://raw.githubusercontent.com/jfjelstul/worldcup/master/data-csv/bookings.csv | AW27: https://footystats.org/c-dl.php?comp=1419&type=matches | AX27: Escanteios por partida indisponiveis no CSV FootyStats desta edicao; nao preencher com estimativa.
A28: 2006 | B28: 2006 FIFA Men's World Cup | C28: M-2006-27 | D28: group stage | E28: Group F | F28: 38886 | G28: 15:00 | H28: Japan | I28: Croatia | J28: 0 | K28: 0 | L28: 0–0 | M28: D | N28: Draw | P28: draw_no_winner | Q28: FALSE | R28: FALSE | S28: 0-0 | W28: dados_insuficientes | X28: 3 | Y28: 2 | Z28: 5 | AA28: 0 | AB28: 0 | AC28: 0 | AD28: 0 | AE28: 0 | AF28: 0 | AG28: 0 | AH28: 0 | AI28: 0 | AJ28: 5 | AK28: ok | AL28: -1 | AM28: -1 | AN28: -1 | AO28: -1 | AP28: -1 | AQ28: -1 | AR28: Frankenstadion | AS28: Nuremberg | AT28: Germany | AU28: https://raw.githubusercontent.com/jfjelstul/worldcup/master/data-csv/matches.csv | AV28: https://raw.githubusercontent.com/jfjelstul/worldcup/master/data-csv/bookings.csv | AW28: https://footystats.org/c-dl.php?comp=1419&type=matches | AX28: Escanteios por partida indisponiveis no CSV FootyStats desta edicao; nao preencher com estimativa.
A29: 2006 | B29: 2006 FIFA Men's World Cup | C29: M-2006-28 | D29: group stage | E29: Group F | F29: 38886 | G29: 18:00 | H29: Brazil | I29: Australia | J29: 2 | K29: 0 | L29: 2–0 | M29: H | N29: Brazil | O29: Brazil | P29: score | Q29: FALSE | R29: FALSE | S29: 0-0 | W29: dados_insuficientes | X29: 3 | Y29: 2 | Z29: 5 | AA29: 0 | AB29: 0 | AC29: 0 | AD29: 0 | AE29: 0 | AF29: 0 | AG29: 0 | AH29: 0 | AI29: 0 | AJ29: 5 | AK29: ok | AL29: -1 | AM29: -1 | AN29: -1 | AO29: -1 | AP29: -1 | AQ29: -1 | AR29: Allianz Arena | AS29: Munich | AT29: Germany | AU29: https://raw.githubusercontent.com/jfjelstul/worldcup/master/data-csv/matches.csv | AV29: https://raw.githubusercontent.com/jfjelstul/worldcup/master/data-csv/bookings.csv | AW29: https://footystats.org/c-dl.php?comp=1419&type=matches | AX29: Escanteios por partida indisponiveis no CSV FootyStats desta edicao; nao preencher com estimativa.
A30: 2006 | B30: 2006 FIFA Men's World Cup | C30: M-2006-29 | D30: group stage | E30: Group G | F30: 38886 | G30: 21:00 | H30: France | I30: South Korea | J30: 1 | K30: 1 | L30: 1–1 | M30: D | N30: Draw | P30: draw_no_winner | Q30: FALSE | R30: FALSE | S30: 0-0 | W30: dados_insuficientes | X30: 2 | Y30: 2 | Z30: 4 | AA30: 0 | AB30: 0 | AC30: 0 | AD30: 0 | AE30: 0 | AF30: 0 | AG30: 0 | AH30: 0 | AI30: 0 | AJ30: 4 | AK30: ok | AL30: -1 | AM30: -1 | AN30: -1 | AO30: -1 | AP30: -1 | AQ30: -1 | AR30: Zentralstadion | AS30: Leipzig | AT30: Germany | AU30: https://raw.githubusercontent.com/jfjelstul/worldcup/master/data-csv/matches.csv | AV30: https://raw.githubusercontent.com/jfjelstul/worldcup/master/data-csv/bookings.csv | AW30: https://footystats.org/c-dl.php?comp=1419&type=matches | AX30: Escanteios por partida indisponiveis no CSV FootyStats desta edicao; nao preencher com estimativa.
A31: 2006 | B31: 2006 FIFA Men's World Cup | C31: M-2006-30 | D31: group stage | E31: Group G | F31: 38887 | G31: 15:00 | H31: Togo | I31: Switzerland | J31: 0 | K31: 2 | L31: 0–2 | M31: A | N31: Switzerland | O31: Switzerland | P31: score | Q31: FALSE | R31: FALSE | S31: 0-0 | W31: dados_insuficientes | X31: 3 | Y31: 1 | Z31: 4 | AA31: 0 | AB31: 0 | AC31: 0 | AD31: 0 | AE31: 0 | AF31: 0 | AG31: 0 | AH31: 0 | AI31: 0 | AJ31: 4 | AK31: ok | AL31: -1 | AM31: -1 | AN31: -1 | AO31: -1 | AP31: -1 | AQ31: -1 | AR31: Westfalenstadion | AS31: Dortmund | AT31: Germany | AU31: https://raw.githubusercontent.com/jfjelstul/worldcup/master/data-csv/matches.csv | AV31: https://raw.githubusercontent.com/jfjelstul/worldcup/master/data-csv/bookings.csv | AW31: https://footystats.org/c-dl.php?comp=1419&type=matches | AX31: Escanteios por partida indisponiveis no CSV FootyStats desta edicao; nao preencher com estimativa.
A32: 2006 | B32: 2006 FIFA Men's World Cup | C32: M-2006-31 | D32: group stage | E32: Group H | F32: 38887 | G32: 18:00 | H32: Saudi Arabia | I32: Ukraine | J32: 0 | K32: 4 | L32: 0–4 | M32: A | N32: Ukraine | O32: Ukraine | P32: score | Q32: FALSE | R32: FALSE | S32: 0-0 | W32: dados_insuficientes | X32: 3 | Y32: 3 | Z32: 6 | AA32: 0 | AB32: 0 | AC32: 0 | AD32: 0 | AE32: 0 | AF32: 0 | AG32: 0 | AH32: 0 | AI32: 0 | AJ32: 6 | AK32: ok | AL32: -1 | AM32: -1 | AN32: -1 | AO32: -1 | AP32: -1 | AQ32: -1 | AR32: Volksparkstadion | AS32: Hamburg | AT32: Germany | AU32: https://raw.githubusercontent.com/jfjelstul/worldcup/master/data-csv/matches.csv | AV32: https://raw.githubusercontent.com/jfjelstul/worldcup/master/data-csv/bookings.csv | AW32: https://footystats.org/c-dl.php?comp=1419&type=matches | AX32: Escanteios por partida indisponiveis no CSV FootyStats desta edicao; nao preencher com estimativa.
A33: 2006 | B33: 2006 FIFA Men's World Cup | C33: M-2006-32 | D33: group stage | E33: Group H | F33: 38887 | G33: 21:00 | H33: Spain | I33: Tunisia | J33: 3 | K33: 1 | L33: 3–1 | M33: H | N33: Spain | O33: Spain | P33: score | Q33: FALSE | R33: FALSE | S33: 0-0 | W33: dados_insuficientes | X33: 2 | Y33: 6 | Z33: 8 | AA33: 0 | AB33: 0 | AC33: 0 | AD33: 0 | AE33: 0 | AF33: 0 | AG33: 0 | AH33: 0 | AI33: 0 | AJ33: 8 | AK33: ok | AL33: -1 | AM33: -1 | AN33: -1 | AO33: -1 | AP33: -1 | AQ33: -1 | AR33: Neckarstadion | AS33: Stuttgart | AT33: Germany | AU33: https://raw.githubusercontent.com/jfjelstul/worldcup/master/data-csv/matches.csv | AV33: https://raw.githubusercontent.com/jfjelstul/worldcup/master/data-csv/bookings.csv | AW33: https://footystats.org/c-dl.php?comp=1419&type=matches | AX33: Escanteios por partida indisponiveis no CSV FootyStats desta edicao; nao preencher com estimativa.
A34: 2006 | B34: 2006 FIFA Men's World Cup | C34: M-2006-33 | D34: group stage | E34: Group A | F34: 38888 | G34: 16:00 | H34: Costa Rica | I34: Poland | J34: 1 | K34: 2 | L34: 1–2 | M34: A | N34: Poland | O34: Poland | P34: score | Q34: FALSE | R34: FALSE | S34: 0-0 | W34: dados_insuficientes | X34: 5 | Y34: 5 | Z34: 10 | AA34: 0 | AB34: 0 | AC34: 0 | AD34: 0 | AE34: 0 | AF34: 0 | AG34: 0 | AH34: 0 | AI34: 0 | AJ34: 10 | AK34: ok | AL34: -1 | AM34: -1 | AN34: -1 | AO34: -1 | AP34: -1 | AQ34: -1 | AR34: Niedersachsenstadion | AS34: Hanover | AT34: Germany | AU34: https://raw.githubusercontent.com/jfjelstul/worldcup/master/data-csv/matches.csv | AV34: https://raw.githubusercontent.com/jfjelstul/worldcup/master/data-csv/bookings.csv | AW34: https://footystats.org/c-dl.php?comp=1419&type=matches | AX34: Escanteios por partida indisponiveis no CSV FootyStats desta edicao; nao preencher com estimativa.
A35: 2006 | B35: 2006 FIFA Men's World Cup | C35: M-2006-34 | D35: group stage | E35: Group A | F35: 38888 | G35: 16:00 | H35: Ecuador | I35: Germany | J35: 0 | K35: 3 | L35: 0–3 | M35: A | N35: Germany | O35: Germany | P35: score | Q35: FALSE | R35: FALSE | S35: 0-0 | W35: dados_insuficientes | X35: 1 | Y35: 1 | Z35: 2 | AA35: 0 | AB35: 0 | AC35: 0 | AD35: 0 | AE35: 0 | AF35: 0 | AG35: 0 | AH35: 0 | AI35: 0 | AJ35: 2 | AK35: ok | AL35: -1 | AM35: -1 | AN35: -1 | AO35: -1 | AP35: -1 | AQ35: -1 | AR35: Olympiastadion | AS35: Berlin | AT35: Germany | AU35: https://raw.githubusercontent.com/jfjelstul/worldcup/master/data-csv/matches.csv | AV35: https://raw.githubusercontent.com/jfjelstul/worldcup/master/data-csv/bookings.csv | AW35: https://footystats.org/c-dl.php?comp=1419&type=matches | AX35: Escanteios por partida indisponiveis no CSV FootyStats desta edicao; nao preencher com estimativa.
A36: 2006 | B36: 2006 FIFA Men's World Cup | C36: M-2006-35 | D36: group stage | E36: Group B | F36: 38888 | G36: 21:00 | H36: Paraguay | I36: Trinidad and Tobago | J36: 2 | K36: 0 | L36: 2–0 | M36: H | N36: Paraguay | O36: Paraguay | P36: score | Q36: FALSE | R36: FALSE | S36: 0-0 | W36: dados_insuficientes | X36: 2 | Y36: 2 | Z36: 4 | AA36: 0 | AB36: 0 | AC36: 0 | AD36: 0 | AE36: 0 | AF36: 0 | AG36: 0 | AH36: 0 | AI36: 0 | AJ36: 4 | AK36: ok | AL36: -1 | AM36: -1 | AN36: -1 | AO36: -1 | AP36: -1 | AQ36: -1 | AR36: Fritz-Walter-Stadion | AS36: Kaiserslautern | AT36: Germany | AU36: https://raw.githubusercontent.com/jfjelstul/worldcup/master/data-csv/matches.csv | AV36: https://raw.githubusercontent.com/jfjelstul/worldcup/master/data-csv/bookings.csv | AW36: https://footystats.org/c-dl.php?comp=1419&type=matches | AX36: Escanteios por partida indisponiveis no CSV FootyStats desta edicao; nao preencher com estimativa.
A37: 2006 | B37: 2006 FIFA Men's World Cup | C37: M-2006-36 | D37: group stage | E37: Group B | F37: 38888 | G37: 21:00 | H37: Sweden | I37: England | J37: 2 | K37: 2 | L37: 2–2 | M37: D | N37: Draw | P37: draw_no_winner | Q37: FALSE | R37: FALSE | S37: 0-0 | W37: dados_insuficientes | X37: 2 | Y37: 1 | Z37: 3 | AA37: 0 | AB37: 0 | AC37: 0 | AD37: 0 | AE37: 0 | AF37: 0 | AG37: 0 | AH37: 0 | AI37: 0 | AJ37: 3 | AK37: ok | AL37: -1 | AM37: -1 | AN37: -1 | AO37: -1 | AP37: -1 | AQ37: -1 | AR37: RheinEnergieStadion | AS37: Cologne | AT37: Germany | AU37: https://raw.githubusercontent.com/jfjelstul/worldcup/master/data-csv/matches.csv | AV37: https://raw.githubusercontent.com/jfjelstul/worldcup/master/data-csv/bookings.csv | AW37: https://footystats.org/c-dl.php?comp=1419&type=matches | AX37: Escanteios por partida indisponiveis no CSV FootyStats desta edicao; nao preencher com estimativa.
A38: 2006 | B38: 2006 FIFA Men's World Cup | C38: M-2006-37 | D38: group stage | E38: Group D | F38: 38889 | G38: 16:00 | H38: Iran | I38: Angola | J38: 1 | K38: 1 | L38: 1–1 | M38: D | N38: Draw | P38: draw_no_winner | Q38: FALSE | R38: FALSE | S38: 0-0 | W38: dados_insuficientes | X38: 3 | Y38: 3 | Z38: 6 | AA38: 0 | AB38: 0 | AC38: 0 | AD38: 0 | AE38: 0 | AF38: 0 | AG38: 0 | AH38: 0 | AI38: 0 | AJ38: 6 | AK38: ok | AL38: -1 | AM38: -1 | AN38: -1 | AO38: -1 | AP38: -1 | AQ38: -1 | AR38: Zentralstadion | AS38: Leipzig | AT38: Germany | AU38: https://raw.githubusercontent.com/jfjelstul/worldcup/master/data-csv/matches.csv | AV38: https://raw.githubusercontent.com/jfjelstul/worldcup/master/data-csv/bookings.csv | AW38: https://footystats.org/c-dl.php?comp=1419&type=matches | AX38: Escanteios por partida indisponiveis no CSV FootyStats desta edicao; nao preencher com estimativa.
A39: 2006 | B39: 2006 FIFA Men's World Cup | C39: M-2006-38 | D39: group stage | E39: Group D | F39: 38889 | G39: 16:00 | H39: Portugal | I39: Mexico | J39: 2 | K39: 1 | L39: 2–1 | M39: H | N39: Portugal | O39: Portugal | P39: score | Q39: FALSE | R39: FALSE | S39: 0-0 | W39: dados_insuficientes | X39: 4 | Y39: 4 | Z39: 8 | AA39: 0 | AB39: 0 | AC39: 0 | AD39: 0 | AE39: 1 | AF39: 1 | AG39: 0 | AH39: 1 | AI39: 1 | AJ39: 9 | AK39: ok | AL39: -1 | AM39: -1 | AN39: -1 | AO39: -1 | AP39: -1 | AQ39: -1 | AR39: Arena AufShalke | AS39: Gelsenkirchen | AT39: Germany | AU39: https://raw.githubusercontent.com/jfjelstul/worldcup/master/data-csv/matches.csv | AV39: https://raw.githubusercontent.com/jfjelstul/worldcup/master/data-csv/bookings.csv | AW39: https://footystats.org/c-dl.php?comp=1419&type=matches | AX39: Escanteios por partida indisponiveis no CSV FootyStats desta edicao; nao preencher com estimativa.
A40: 2006 | B40: 2006 FIFA Men's World Cup | C40: M-2006-39 | D40: group stage | E40: Group C | F40: 38889 | G40: 21:00 | H40: Ivory Coast | I40: Serbia and Montenegro | J40: 3 | K40: 2 | L40: 3–2 | M40: H | N40: Ivory Coast | O40: Ivory Coast | P40: score | Q40: FALSE | R40: FALSE | S40: 0-0 | W40: dados_insuficientes | X40: 3 | Y40: 4 | Z40: 7 | AA40: 0 | AB40: 0 | AC40: 0 | AD40: 1 | AE40: 1 | AF40: 2 | AG40: 1 | AH40: 1 | AI40: 2 | AJ40: 9 | AK40: ok | AL40: -1 | AM40: -1 | AN40: -1 | AO40: -1 | AP40: -1 | AQ40: -1 | AR40: Allianz Arena | AS40: Munich | AT40: Germany | AU40: https://raw.githubusercontent.com/jfjelstul/worldcup/master/data-csv/matches.csv | AV40: https://raw.githubusercontent.com/jfjelstul/worldcup/master/data-csv/bookings.csv | AW40: https://footystats.org/c-dl.php?comp=1419&type=matches | AX40: Escanteios por partida indisponiveis no CSV FootyStats desta edicao; nao preencher com estimativa.
...

Sheet Labels_Modelo
A1: match_id | B1: match_date | C1: competition_year | D1: home_team | E1: away_team | F1: FTHG | G1: FTAG | H1: FTR | I1: totalGoals | J1: over15 | K1: over25 | L1: over35 | M1: under25 | N1: under35 | O1: bothTeamsScore | P1: doubleChance_1X | Q1: doubleChance_12 | R1: doubleChance_X2 | S1: HC | T1: AC | U1: totalCorners | V1: corners_over85 | W1: corners_over95 | X1: HY | Y1: AY | Z1: HR | AA1: AR | AB1: totalCards | AC1: cards_over35 | AD1: cards_over45 | AE1: cards_over55 | AF1: corners_status | AG1: cards_status | AH1: source_provider | AI1: data_note
A2: =Partidas!C2 -> M-2006-01 | B2: =Partidas!F2 -> 38877 | C2: =Partidas!A2 -> 2006 | D2: =Partidas!H2 -> Germany | E2: =Partidas!I2 -> Costa Rica | F2: =Partidas!J2 -> 4 | G2: =Partidas!K2 -> 2 | H2: =Partidas!M2 -> H | I2: =F2+G2 -> 6 | J2: =I2>1.5 -> TRUE | K2: =I2>2.5 -> TRUE | L2: =I2>3.5 -> TRUE | M2: =I2<2.5 -> FALSE | N2: =I2<3.5 -> FALSE | O2: =AND(F2>0,G2>0) -> TRUE | P2: =OR(H2="H",H2="D") -> TRUE | Q2: =OR(H2="H",H2="A") -> TRUE | R2: =OR(H2="D",H2="A") -> FALSE | S2: =Partidas!T2 -> 0 | T2: =Partidas!U2 -> 0 | U2: =IF(OR(S2="",T2=""),"",S2+T2) -> 0 | V2: =IF(U2="","dados_insuficientes",U2>8.5) -> FALSE | W2: =IF(U2="","dados_insuficientes",U2>9.5) -> FALSE | X2: =Partidas!X2 -> 0 | Y2: =Partidas!Y2 -> 1 | Z2: =Partidas!AG2 -> 0 | AA2: =Partidas!AH2 -> 0 | AB2: =X2+Y2+Z2+AA2 -> 1 | AC2: =AB2>3.5 -> FALSE | AD2: =AB2>4.5 -> FALSE | AE2: =AB2>5.5 -> FALSE | AF2: =Partidas!W2 -> dados_insuficientes | AG2: =Partidas!AK2 -> ok | AH2: ="Fjelstul World Cup Database + FootyStats CSV" -> Fjelstul World Cup Database + FootyStats CSV | AI2: =Partidas!AX2 -> Escanteios por partida indisponiveis no CSV FootyStats desta edicao; nao preencher com estimativa.
A3: =Partidas!C3 -> M-2006-02 | B3: =Partidas!F3 -> 38877 | C3: =Partidas!A3 -> 2006 | D3: =Partidas!H3 -> Poland | E3: =Partidas!I3 -> Ecuador | F3: =Partidas!J3 -> 0 | G3: =Partidas!K3 -> 2 | H3: =Partidas!M3 -> A | I3: =F3+G3 -> 2 | J3: =I3>1.5 -> TRUE | K3: =I3>2.5 -> FALSE | L3: =I3>3.5 -> FALSE | M3: =I3<2.5 -> TRUE | N3: =I3<3.5 -> TRUE | O3: =AND(F3>0,G3>0) -> FALSE | P3: =OR(H3="H",H3="D") -> FALSE | Q3: =OR(H3="H",H3="A") -> TRUE | R3: =OR(H3="D",H3="A") -> TRUE | S3: =Partidas!T3 -> 0 | T3: =Partidas!U3 -> 0 | U3: =IF(OR(S3="",T3=""),"",S3+T3) -> 0 | V3: =IF(U3="","dados_insuficientes",U3>8.5) -> FALSE | W3: =IF(U3="","dados_insuficientes",U3>9.5) -> FALSE | X3: =Partidas!X3 -> 1 | Y3: =Partidas!Y3 -> 2 | Z3: =Partidas!AG3 -> 0 | AA3: =Partidas!AH3 -> 0 | AB3: =X3+Y3+Z3+AA3 -> 3 | AC3: =AB3>3.5 -> FALSE | AD3: =AB3>4.5 -> FALSE | AE3: =AB3>5.5 -> FALSE | AF3: =Partidas!W3 -> dados_insuficientes | AG3: =Partidas!AK3 -> ok | AH3: ="Fjelstul World Cup Database + FootyStats CSV" -> Fjelstul World Cup Database + FootyStats CSV | AI3: =Partidas!AX3 -> Escanteios por partida indisponiveis no CSV FootyStats desta edicao; nao preencher com estimativa.
A4: =Partidas!C4 -> M-2006-03 | B4: =Partidas!F4 -> 38878 | C4: =Partidas!A4 -> 2006 | D4: =Partidas!H4 -> England | E4: =Partidas!I4 -> Paraguay | F4: =Partidas!J4 -> 1 | G4: =Partidas!K4 -> 0 | H4: =Partidas!M4 -> H | I4: =F4+G4 -> 1 | J4: =I4>1.5 -> FALSE | K4: =I4>2.5 -> FALSE | L4: =I4>3.5 -> FALSE | M4: =I4<2.5 -> TRUE | N4: =I4<3.5 -> TRUE | O4: =AND(F4>0,G4>0) -> FALSE | P4: =OR(H4="H",H4="D") -> TRUE | Q4: =OR(H4="H",H4="A") -> TRUE | R4: =OR(H4="D",H4="A") -> FALSE | S4: =Partidas!T4 -> 0 | T4: =Partidas!U4 -> 0 | U4: =IF(OR(S4="",T4=""),"",S4+T4) -> 0 | V4: =IF(U4="","dados_insuficientes",U4>8.5) -> FALSE | W4: =IF(U4="","dados_insuficientes",U4>9.5) -> FALSE | X4: =Partidas!X4 -> 2 | Y4: =Partidas!Y4 -> 1 | Z4: =Partidas!AG4 -> 0 | AA4: =Partidas!AH4 -> 0 | AB4: =X4+Y4+Z4+AA4 -> 3 | AC4: =AB4>3.5 -> FALSE | AD4: =AB4>4.5 -> FALSE | AE4: =AB4>5.5 -> FALSE | AF4: =Partidas!W4 -> dados_insuficientes | AG4: =Partidas!AK4 -> ok | AH4: ="Fjelstul World Cup Database + FootyStats CSV" -> Fjelstul World Cup Database + FootyStats CSV | AI4: =Partidas!AX4 -> Escanteios por partida indisponiveis no CSV FootyStats desta edicao; nao preencher com estimativa.
A5: =Partidas!C5 -> M-2006-04 | B5: =Partidas!F5 -> 38878 | C5: =Partidas!A5 -> 2006 | D5: =Partidas!H5 -> Trinidad and Tobago | E5: =Partidas!I5 -> Sweden | F5: =Partidas!J5 -> 0 | G5: =Partidas!K5 -> 0 | H5: =Partidas!M5 -> D | I5: =F5+G5 -> 0 | J5: =I5>1.5 -> FALSE | K5: =I5>2.5 -> FALSE | L5: =I5>3.5 -> FALSE | M5: =I5<2.5 -> TRUE | N5: =I5<3.5 -> TRUE | O5: =AND(F5>0,G5>0) -> FALSE | P5: =OR(H5="H",H5="D") -> TRUE | Q5: =OR(H5="H",H5="A") -> FALSE | R5: =OR(H5="D",H5="A") -> TRUE | S5: =Partidas!T5 -> 0 | T5: =Partidas!U5 -> 0 | U5: =IF(OR(S5="",T5=""),"",S5+T5) -> 0 | V5: =IF(U5="","dados_insuficientes",U5>8.5) -> FALSE | W5: =IF(U5="","dados_insuficientes",U5>9.5) -> FALSE | X5: =Partidas!X5 -> 2 | Y5: =Partidas!Y5 -> 1 | Z5: =Partidas!AG5 -> 1 | AA5: =Partidas!AH5 -> 0 | AB5: =X5+Y5+Z5+AA5 -> 4 | AC5: =AB5>3.5 -> TRUE | AD5: =AB5>4.5 -> FALSE | AE5: =AB5>5.5 -> FALSE | AF5: =Partidas!W5 -> dados_insuficientes | AG5: =Partidas!AK5 -> ok | AH5: ="Fjelstul World Cup Database + FootyStats CSV" -> Fjelstul World Cup Database + FootyStats CSV | AI5: =Partidas!AX5 -> Escanteios por partida indisponiveis no CSV FootyStats desta edicao; nao preencher com estimativa.
A6: =Partidas!C6 -> M-2006-05 | B6: =Partidas!F6 -> 38878 | C6: =Partidas!A6 -> 2006 | D6: =Partidas!H6 -> Argentina | E6: =Partidas!I6 -> Ivory Coast | F6: =Partidas!J6 -> 2 | G6: =Partidas!K6 -> 1 | H6: =Partidas!M6 -> H | I6: =F6+G6 -> 3 | J6: =I6>1.5 -> TRUE | K6: =I6>2.5 -> TRUE | L6: =I6>3.5 -> FALSE | M6: =I6<2.5 -> FALSE | N6: =I6<3.5 -> TRUE | O6: =AND(F6>0,G6>0) -> TRUE | P6: =OR(H6="H",H6="D") -> TRUE | Q6: =OR(H6="H",H6="A") -> TRUE | R6: =OR(H6="D",H6="A") -> FALSE | S6: =Partidas!T6 -> 0 | T6: =Partidas!U6 -> 0 | U6: =IF(OR(S6="",T6=""),"",S6+T6) -> 0 | V6: =IF(U6="","dados_insuficientes",U6>8.5) -> FALSE | W6: =IF(U6="","dados_insuficientes",U6>9.5) -> FALSE | X6: =Partidas!X6 -> 3 | Y6: =Partidas!Y6 -> 2 | Z6: =Partidas!AG6 -> 0 | AA6: =Partidas!AH6 -> 0 | AB6: =X6+Y6+Z6+AA6 -> 5 | AC6: =AB6>3.5 -> TRUE | AD6: =AB6>4.5 -> TRUE | AE6: =AB6>5.5 -> FALSE | AF6: =Partidas!W6 -> dados_insuficientes | AG6: =Partidas!AK6 -> ok | AH6: ="Fjelstul World Cup Database + FootyStats CSV" -> Fjelstul World Cup Database + FootyStats CSV | AI6: =Partidas!AX6 -> Escanteios por partida indisponiveis no CSV FootyStats desta edicao; nao preencher com estimativa.
A7: =Partidas!C7 -> M-2006-06 | B7: =Partidas!F7 -> 38879 | C7: =Partidas!A7 -> 2006 | D7: =Partidas!H7 -> Serbia and Montenegro | E7: =Partidas!I7 -> Netherlands | F7: =Partidas!J7 -> 0 | G7: =Partidas!K7 -> 1 | H7: =Partidas!M7 -> A | I7: =F7+G7 -> 1 | J7: =I7>1.5 -> FALSE | K7: =I7>2.5 -> FALSE | L7: =I7>3.5 -> FALSE | M7: =I7<2.5 -> TRUE | N7: =I7<3.5 -> TRUE | O7: =AND(F7>0,G7>0) -> FALSE | P7: =OR(H7="H",H7="D") -> FALSE | Q7: =OR(H7="H",H7="A") -> TRUE | R7: =OR(H7="D",H7="A") -> TRUE | S7: =Partidas!T7 -> 0 | T7: =Partidas!U7 -> 0 | U7: =IF(OR(S7="",T7=""),"",S7+T7) -> 0 | V7: =IF(U7="","dados_insuficientes",U7>8.5) -> FALSE | W7: =IF(U7="","dados_insuficientes",U7>9.5) -> FALSE | X7: =Partidas!X7 -> 4 | Y7: =Partidas!Y7 -> 2 | Z7: =Partidas!AG7 -> 0 | AA7: =Partidas!AH7 -> 0 | AB7: =X7+Y7+Z7+AA7 -> 6 | AC7: =AB7>3.5 -> TRUE | AD7: =AB7>4.5 -> TRUE | AE7: =AB7>5.5 -> TRUE | AF7: =Partidas!W7 -> dados_insuficientes | AG7: =Partidas!AK7 -> ok | AH7: ="Fjelstul World Cup Database + FootyStats CSV" -> Fjelstul World Cup Database + FootyStats CSV | AI7: =Partidas!AX7 -> Escanteios por partida indisponiveis no CSV FootyStats desta edicao; nao preencher com estimativa.
A8: =Partidas!C8 -> M-2006-07 | B8: =Partidas!F8 -> 38879 | C8: =Partidas!A8 -> 2006 | D8: =Partidas!H8 -> Mexico | E8: =Partidas!I8 -> Iran | F8: =Partidas!J8 -> 3 | G8: =Partidas!K8 -> 1 | H8: =Partidas!M8 -> H | I8: =F8+G8 -> 4 | J8: =I8>1.5 -> TRUE | K8: =I8>2.5 -> TRUE | L8: =I8>3.5 -> TRUE | M8: =I8<2.5 -> FALSE | N8: =I8<3.5 -> FALSE | O8: =AND(F8>0,G8>0) -> TRUE | P8: =OR(H8="H",H8="D") -> TRUE | Q8: =OR(H8="H",H8="A") -> TRUE | R8: =OR(H8="D",H8="A") -> FALSE | S8: =Partidas!T8 -> 0 | T8: =Partidas!U8 -> 0 | U8: =IF(OR(S8="",T8=""),"",S8+T8) -> 0 | V8: =IF(U8="","dados_insuficientes",U8>8.5) -> FALSE | W8: =IF(U8="","dados_insuficientes",U8>9.5) -> FALSE | X8: =Partidas!X8 -> 2 | Y8: =Partidas!Y8 -> 1 | Z8: =Partidas!AG8 -> 0 | AA8: =Partidas!AH8 -> 0 | AB8: =X8+Y8+Z8+AA8 -> 3 | AC8: =AB8>3.5 -> FALSE | AD8: =AB8>4.5 -> FALSE | AE8: =AB8>5.5 -> FALSE | AF8: =Partidas!W8 -> dados_insuficientes | AG8: =Partidas!AK8 -> ok | AH8: ="Fjelstul World Cup Database + FootyStats CSV" -> Fjelstul World Cup Database + FootyStats CSV | AI8: =Partidas!AX8 -> Escanteios por partida indisponiveis no CSV FootyStats desta edicao; nao preencher com estimativa.
A9: =Partidas!C9 -> M-2006-08 | B9: =Partidas!F9 -> 38879 | C9: =Partidas!A9 -> 2006 | D9: =Partidas!H9 -> Angola | E9: =Partidas!I9 -> Portugal | F9: =Partidas!J9 -> 0 | G9: =Partidas!K9 -> 1 | H9: =Partidas!M9 -> A | I9: =F9+G9 -> 1 | J9: =I9>1.5 -> FALSE | K9: =I9>2.5 -> FALSE | L9: =I9>3.5 -> FALSE | M9: =I9<2.5 -> TRUE | N9: =I9<3.5 -> TRUE | O9: =AND(F9>0,G9>0) -> FALSE | P9: =OR(H9="H",H9="D") -> FALSE | Q9: =OR(H9="H",H9="A") -> TRUE | R9: =OR(H9="D",H9="A") -> TRUE | S9: =Partidas!T9 -> 0 | T9: =Partidas!U9 -> 0 | U9: =IF(OR(S9="",T9=""),"",S9+T9) -> 0 | V9: =IF(U9="","dados_insuficientes",U9>8.5) -> FALSE | W9: =IF(U9="","dados_insuficientes",U9>9.5) -> FALSE | X9: =Partidas!X9 -> 3 | Y9: =Partidas!Y9 -> 2 | Z9: =Partidas!AG9 -> 0 | AA9: =Partidas!AH9 -> 0 | AB9: =X9+Y9+Z9+AA9 -> 5 | AC9: =AB9>3.5 -> TRUE | AD9: =AB9>4.5 -> TRUE | AE9: =AB9>5.5 -> FALSE | AF9: =Partidas!W9 -> dados_insuficientes | AG9: =Partidas!AK9 -> ok | AH9: ="Fjelstul World Cup Database + FootyStats CSV" -> Fjelstul World Cup Database + FootyStats CSV | AI9: =Partidas!AX9 -> Escanteios por partida indisponiveis no CSV FootyStats desta edicao; nao preencher com estimativa.
A10: =Partidas!C10 -> M-2006-09 | B10: =Partidas!F10 -> 38880 | C10: =Partidas!A10 -> 2006 | D10: =Partidas!H10 -> Australia | E10: =Partidas!I10 -> Japan | F10: =Partidas!J10 -> 3 | G10: =Partidas!K10 -> 1 | H10: =Partidas!M10 -> H | I10: =F10+G10 -> 4 | J10: =I10>1.5 -> TRUE | K10: =I10>2.5 -> TRUE | L10: =I10>3.5 -> TRUE | M10: =I10<2.5 -> FALSE | N10: =I10<3.5 -> FALSE | O10: =AND(F10>0,G10>0) -> TRUE | P10: =OR(H10="H",H10="D") -> TRUE | Q10: =OR(H10="H",H10="A") -> TRUE | R10: =OR(H10="D",H10="A") -> FALSE | S10: =Partidas!T10 -> 0 | T10: =Partidas!U10 -> 0 | U10: =IF(OR(S10="",T10=""),"",S10+T10) -> 0 | V10: =IF(U10="","dados_insuficientes",U10>8.5) -> FALSE | W10: =IF(U10="","dados_insuficientes",U10>9.5) -> FALSE | X10: =Partidas!X10 -> 4 | Y10: =Partidas!Y10 -> 3 | Z10: =Partidas!AG10 -> 0 | AA10: =Partidas!AH10 -> 0 | AB10: =X10+Y10+Z10+AA10 -> 7 | AC10: =AB10>3.5 -> TRUE | AD10: =AB10>4.5 -> TRUE | AE10: =AB10>5.5 -> TRUE | AF10: =Partidas!W10 -> dados_insuficientes | AG10: =Partidas!AK10 -> ok | AH10: ="Fjelstul World Cup Database + FootyStats CSV" -> Fjelstul World Cup Database + FootyStats CSV | AI10: =Partidas!AX10 -> Escanteios por partida indisponiveis no CSV FootyStats desta edicao; nao preencher com estimativa.
A11: =Partidas!C11 -> M-2006-10 | B11: =Partidas!F11 -> 38880 | C11: =Partidas!A11 -> 2006 | D11: =Partidas!H11 -> United States | E11: =Partidas!I11 -> Czech Republic | F11: =Partidas!J11 -> 0 | G11: =Partidas!K11 -> 3 | H11: =Partidas!M11 -> A | I11: =F11+G11 -> 3 | J11: =I11>1.5 -> TRUE | K11: =I11>2.5 -> TRUE | L11: =I11>3.5 -> FALSE | M11: =I11<2.5 -> FALSE | N11: =I11<3.5 -> TRUE | O11: =AND(F11>0,G11>0) -> FALSE | P11: =OR(H11="H",H11="D") -> FALSE | Q11: =OR(H11="H",H11="A") -> TRUE | R11: =OR(H11="D",H11="A") -> TRUE | S11: =Partidas!T11 -> 0 | T11: =Partidas!U11 -> 0 | U11: =IF(OR(S11="",T11=""),"",S11+T11) -> 0 | V11: =IF(U11="","dados_insuficientes",U11>8.5) -> FALSE | W11: =IF(U11="","dados_insuficientes",U11>9.5) -> FALSE | X11: =Partidas!X11 -> 2 | Y11: =Partidas!Y11 -> 4 | Z11: =Partidas!AG11 -> 0 | AA11: =Partidas!AH11 -> 0 | AB11: =X11+Y11+Z11+AA11 -> 6 | AC11: =AB11>3.5 -> TRUE | AD11: =AB11>4.5 -> TRUE | AE11: =AB11>5.5 -> TRUE | AF11: =Partidas!W11 -> dados_insuficientes | AG11: =Partidas!AK11 -> ok | AH11: ="Fjelstul World Cup Database + FootyStats CSV" -> Fjelstul World Cup Database + FootyStats CSV | AI11: =Partidas!AX11 -> Escanteios por partida indisponiveis no CSV FootyStats desta edicao; nao preencher com estimativa.
A12: =Partidas!C12 -> M-2006-11 | B12: =Partidas!F12 -> 38880 | C12: =Partidas!A12 -> 2006 | D12: =Partidas!H12 -> Italy | E12: =Partidas!I12 -> Ghana | F12: =Partidas!J12 -> 2 | G12: =Partidas!K12 -> 0 | H12: =Partidas!M12 -> H | I12: =F12+G12 -> 2 | J12: =I12>1.5 -> TRUE | K12: =I12>2.5 -> FALSE | L12: =I12>3.5 -> FALSE | M12: =I12<2.5 -> TRUE | N12: =I12<3.5 -> TRUE | O12: =AND(F12>0,G12>0) -> FALSE | P12: =OR(H12="H",H12="D") -> TRUE | Q12: =OR(H12="H",H12="A") -> TRUE | R12: =OR(H12="D",H12="A") -> FALSE | S12: =Partidas!T12 -> 0 | T12: =Partidas!U12 -> 0 | U12: =IF(OR(S12="",T12=""),"",S12+T12) -> 0 | V12: =IF(U12="","dados_insuficientes",U12>8.5) -> FALSE | W12: =IF(U12="","dados_insuficientes",U12>9.5) -> FALSE | X12: =Partidas!X12 -> 3 | Y12: =Partidas!Y12 -> 2 | Z12: =Partidas!AG12 -> 0 | AA12: =Partidas!AH12 -> 0 | AB12: =X12+Y12+Z12+AA12 -> 5 | AC12: =AB12>3.5 -> TRUE | AD12: =AB12>4.5 -> TRUE | AE12: =AB12>5.5 -> FALSE | AF12: =Partidas!W12 -> dados_insuficientes | AG12: =Partidas!AK12 -> ok | AH12: ="Fjelstul World Cup Database + FootyStats CSV" -> Fjelstul World Cup Database + FootyStats CSV | AI12: =Partidas!AX12 -> Escanteios por partida indisponiveis no CSV FootyStats desta edicao; nao preencher com estimativa.
A13: =Partidas!C13 -> M-2006-12 | B13: =Partidas!F13 -> 38881 | C13: =Partidas!A13 -> 2006 | D13: =Partidas!H13 -> South Korea | E13: =Partidas!I13 -> Togo | F13: =Partidas!J13 -> 2 | G13: =Partidas!K13 -> 1 | H13: =Partidas!M13 -> H | I13: =F13+G13 -> 3 | J13: =I13>1.5 -> TRUE | K13: =I13>2.5 -> TRUE | L13: =I13>3.5 -> FALSE | M13: =I13<2.5 -> FALSE | N13: =I13<3.5 -> TRUE | O13: =AND(F13>0,G13>0) -> TRUE | P13: =OR(H13="H",H13="D") -> TRUE | Q13: =OR(H13="H",H13="A") -> TRUE | R13: =OR(H13="D",H13="A") -> FALSE | S13: =Partidas!T13 -> 0 | T13: =Partidas!U13 -> 0 | U13: =IF(OR(S13="",T13=""),"",S13+T13) -> 0 | V13: =IF(U13="","dados_insuficientes",U13>8.5) -> FALSE | W13: =IF(U13="","dados_insuficientes",U13>9.5) -> FALSE | X13: =Partidas!X13 -> 2 | Y13: =Partidas!Y13 -> 3 | Z13: =Partidas!AG13 -> 0 | AA13: =Partidas!AH13 -> 1 | AB13: =X13+Y13+Z13+AA13 -> 6 | AC13: =AB13>3.5 -> TRUE | AD13: =AB13>4.5 -> TRUE | AE13: =AB13>5.5 -> TRUE | AF13: =Partidas!W13 -> dados_insuficientes | AG13: =Partidas!AK13 -> ok | AH13: ="Fjelstul World Cup Database + FootyStats CSV" -> Fjelstul World Cup Database + FootyStats CSV | AI13: =Partidas!AX13 -> Escanteios por partida indisponiveis no CSV FootyStats desta edicao; nao preencher com estimativa.
... A321: =Partidas!C321 -> M-2022-64 | B321: =Partidas!F321 -> 44913 | C321: =Partidas!A321 -> 2022 | D321: =Partidas!H321 -> Argentina | E321: =Partidas!I321 -> France | F321: =Partidas!J321 -> 3 | G321: =Partidas!K321 -> 3 | H321: =Partidas!M321 -> D | I321: =F321+G321 -> 6 | J321: =I321>1.5 -> TRUE | K321: =I321>2.5 -> TRUE | L321: =I321>3.5 -> TRUE | M321: =I321<2.5 -> FALSE | N321: =I321<3.5 -> FALSE | O321: =AND(F321>0,G321>0) -> TRUE | P321: =OR(H321="H",H321="D") -> TRUE | Q321: =OR(H321="H",H321="A") -> FALSE | R321: =OR(H321="D",H321="A") -> TRUE | S321: =Partidas!T321 -> 6 | T321: =Partidas!U321 -> 5 | U321: =IF(OR(S321="",T321=""),"",S321+T321) -> 11 | V321: =IF(U321="","dados_insuficientes",U321>8.5) -> TRUE | W321: =IF(U321="","dados_insuficientes",U321>9.5) -> TRUE | X321: =Partidas!X321 -> 5 | Y321: =Partidas!Y321 -> 3 | Z321: =Partidas!AG321 -> 0 | AA321: =Partidas!AH321 -> 0 | AB321: =X321+Y321+Z321+AA321 -> 8 | AC321: =AB321>3.5 -> TRUE | AD321: =AB321>4.5 -> TRUE | AE321: =AB321>5.5 -> TRUE | AF321: =Partidas!W321 -> ok | AG321: =Partidas!AK321 -> ok | AH321: ="Fjelstul World Cup Database + FootyStats CSV" -> Fjelstul World Cup Database + FootyStats CSV | AI321: =Partidas!AX321 -> 0

Sheet Por_Edicao
A1: Ano | B1: Partidas | C1: Gols | D1: Media gols | E1: H | F1: D | G1: A | H1: Partidas com escanteios | I1: Total escanteios | J1: Media escanteios | K1: Total amarelos | L1: Total expulsoes | M1: TotalCards modelo | N1: Media cards modelo
A2: 2006 | B2: =COUNTIF(Partidas!$A$2:$A$321,A2) -> 64 | C2: =SUMIF(Partidas!$A$2:$A$321,A2,Partidas!$J$2:$J$321)+SUMIF(Partidas!$A$2:$A$321,A2,Partidas!$K$2:$K$321) -> 147 | D2: =C2/B2 -> 2.296875 | E2: =COUNTIFS(Partidas!$A$2:$A$321,A2,Partidas!$M$2:$M$321,"H") -> 32 | F2: =COUNTIFS(Partidas!$A$2:$A$321,A2,Partidas!$M$2:$M$321,"D") -> 15 | G2: =COUNTIFS(Partidas!$A$2:$A$321,A2,Partidas!$M$2:$M$321,"A") -> 17 | H2: =COUNTIFS(Partidas!$A$2:$A$321,A2,Partidas!$W$2:$W$321,"ok") -> 0 | I2: =SUMIFS(Partidas!$V$2:$V$321,Partidas!$A$2:$A$321,A2) -> 0 | J2: =IF(H2=0,"dados_insuficientes",I2/H2) -> dados_insuficientes | K2: =SUMIFS(Partidas!$Z$2:$Z$321,Partidas!$A$2:$A$321,A2) -> 326 | L2: =SUMIFS(Partidas!$AI$2:$AI$321,Partidas!$A$2:$A$321,A2) -> 28 | M2: =SUMIFS(Partidas!$AJ$2:$AJ$321,Partidas!$A$2:$A$321,A2) -> 354 | N2: =M2/B2 -> 5.53125
A3: 2010 | B3: =COUNTIF(Partidas!$A$2:$A$321,A3) -> 64 | C3: =SUMIF(Partidas!$A$2:$A$321,A3,Partidas!$J$2:$J$321)+SUMIF(Partidas!$A$2:$A$321,A3,Partidas!$K$2:$K$321) -> 145 | D3: =C3/B3 -> 2.265625 | E3: =COUNTIFS(Partidas!$A$2:$A$321,A3,Partidas!$M$2:$M$321,"H") -> 23 | F3: =COUNTIFS(Partidas!$A$2:$A$321,A3,Partidas!$M$2:$M$321,"D") -> 16 | G3: =COUNTIFS(Partidas!$A$2:$A$321,A3,Partidas!$M$2:$M$321,"A") -> 25 | H3: =COUNTIFS(Partidas!$A$2:$A$321,A3,Partidas!$W$2:$W$321,"ok") -> 64 | I3: =SUMIFS(Partidas!$V$2:$V$321,Partidas!$A$2:$A$321,A3) -> 620 | J3: =IF(H3=0,"dados_insuficientes",I3/H3) -> 9.6875 | K3: =SUMIFS(Partidas!$Z$2:$Z$321,Partidas!$A$2:$A$321,A3) -> 254 | L3: =SUMIFS(Partidas!$AI$2:$AI$321,Partidas!$A$2:$A$321,A3) -> 17 | M3: =SUMIFS(Partidas!$AJ$2:$AJ$321,Partidas!$A$2:$A$321,A3) -> 271 | N3: =M3/B3 -> 4.234375
A4: 2014 | B4: =COUNTIF(Partidas!$A$2:$A$321,A4) -> 64 | C4: =SUMIF(Partidas!$A$2:$A$321,A4,Partidas!$J$2:$J$321)+SUMIF(Partidas!$A$2:$A$321,A4,Partidas!$K$2:$K$321) -> 171 | D4: =C4/B4 -> 2.671875 | E4: =COUNTIFS(Partidas!$A$2:$A$321,A4,Partidas!$M$2:$M$321,"H") -> 28 | F4: =COUNTIFS(Partidas!$A$2:$A$321,A4,Partidas!$M$2:$M$321,"D") -> 13 | G4: =COUNTIFS(Partidas!$A$2:$A$321,A4,Partidas!$M$2:$M$321,"A") -> 23 | H4: =COUNTIFS(Partidas!$A$2:$A$321,A4,Partidas!$W$2:$W$321,"ok") -> 64 | I4: =SUMIFS(Partidas!$V$2:$V$321,Partidas!$A$2:$A$321,A4) -> 668 | J4: =IF(H4=0,"dados_insuficientes",I4/H4) -> 10.4375 | K4: =SUMIFS(Partidas!$Z$2:$Z$321,Partidas!$A$2:$A$321,A4) -> 184 | L4: =SUMIFS(Partidas!$AI$2:$AI$321,Partidas!$A$2:$A$321,A4) -> 10 | M4: =SUMIFS(Partidas!$AJ$2:$AJ$321,Partidas!$A$2:$A$321,A4) -> 194 | N4: =M4/B4 -> 3.03125
A5: 2018 | B5: =COUNTIF(Partidas!$A$2:$A$321,A5) -> 64 | C5: =SUMIF(Partidas!$A$2:$A$321,A5,Partidas!$J$2:$J$321)+SUMIF(Partidas!$A$2:$A$321,A5,Partidas!$K$2:$K$321) -> 169 | D5: =C5/B5 -> 2.640625 | E5: =COUNTIFS(Partidas!$A$2:$A$321,A5,Partidas!$M$2:$M$321,"H") -> 26 | F5: =COUNTIFS(Partidas!$A$2:$A$321,A5,Partidas!$M$2:$M$321,"D") -> 13 | G5: =COUNTIFS(Partidas!$A$2:$A$321,A5,Partidas!$M$2:$M$321,"A") -> 25 | H5: =COUNTIFS(Partidas!$A$2:$A$321,A5,Partidas!$W$2:$W$321,"ok") -> 64 | I5: =SUMIFS(Partidas!$V$2:$V$321,Partidas!$A$2:$A$321,A5) -> 597 | J5: =IF(H5=0,"dados_insuficientes",I5/H5) -> 9.328125 | K5: =SUMIFS(Partidas!$Z$2:$Z$321,Partidas!$A$2:$A$321,A5) -> 221 | L5: =SUMIFS(Partidas!$AI$2:$AI$321,Partidas!$A$2:$A$321,A5) -> 4 | M5: =SUMIFS(Partidas!$AJ$2:$AJ$321,Partidas!$A$2:$A$321,A5) -> 225 | N5: =M5/B5 -> 3.515625
A6: 2022 | B6: =COUNTIF(Partidas!$A$2:$A$321,A6) -> 64 | C6: =SUMIF(Partidas!$A$2:$A$321,A6,Partidas!$J$2:$J$321)+SUMIF(Partidas!$A$2:$A$321,A6,Partidas!$K$2:$K$321) -> 172 | D6: =C6/B6 -> 2.6875 | E6: =COUNTIFS(Partidas!$A$2:$A$321,A6,Partidas!$M$2:$M$321,"H") -> 29 | F6: =COUNTIFS(Partidas!$A$2:$A$321,A6,Partidas!$M$2:$M$321,"D") -> 15 | G6: =COUNTIFS(Partidas!$A$2:$A$321,A6,Partidas!$M$2:$M$321,"A") -> 20 | H6: =COUNTIFS(Partidas!$A$2:$A$321,A6,Partidas!$W$2:$W$321,"ok") -> 64 | I6: =SUMIFS(Partidas!$V$2:$V$321,Partidas!$A$2:$A$321,A6) -> 572 | J6: =IF(H6=0,"dados_insuficientes",I6/H6) -> 8.9375 | K6: =SUMIFS(Partidas!$Z$2:$Z$321,Partidas!$A$2:$A$321,A6) -> 224 | L6: =SUMIFS(Partidas!$AI$2:$AI$321,Partidas!$A$2:$A$321,A6) -> 4 | M6: =SUMIFS(Partidas!$AJ$2:$AJ$321,Partidas!$A$2:$A$321,A6) -> 228 | N6: =M6/B6 -> 3.5625

Sheet Dicionario
A1: Coluna | B1: Aba | C1: Descricao
A2: FTHG / FTAG | B2: Labels_Modelo | C2: Gols do mandante/visitante no placar final da fonte, excluindo disputa de penaltis.
A3: FTR | B3: Labels_Modelo | C3: Resultado derivado do placar: H, D ou A.
A4: official_winner | B4: Partidas | C4: Vencedor oficial segundo a base Fjelstul; em jogos decididos nos penaltis pode diferir de FTR.
A5: HC / AC | B5: Labels_Modelo | C5: Escanteios mandante/visitante. Vazio quando a fonte traz valor ausente.
A6: HY / AY | B6: Labels_Modelo | C6: Cartoes amarelos por equipe agregados de bookings.csv.
A7: HR / AR | B7: Labels_Modelo | C7: Expulsoes por equipe: vermelho direto ou segundo amarelo, via sending_off.
A8: totalCards | B8: Labels_Modelo | C8: HY + AY + HR + AR, coerente com o harness BetIntel.
A9: corners_status | B9: Labels_Modelo | C9: ok ou dados_insuficientes; 2006 fica insuficiente para escanteios por partida.
A10: cards_status | B10: Labels_Modelo | C10: ok nas cinco edicoes porque bookings.csv cobre os torneios.
A11: odds | B11: Todas | C11: Odds reais nao foram importadas para evitar uso como recomendacao financeira.

Sheet Fontes_Limitacoes
A1: Tipo | B1: Fonte | C1: URL | D1: Uso na planilha | E1: Licenca/observacao
A2: Resultados e metadados | B2: Fjelstul World Cup Database | C2: https://github.com/jfjelstul/worldcup | D2: Partidas, placares, sede, fase, prorrogacao, penaltis e IDs de partida. | E2: Repositorio informa CC-BY-SA 4.0; manter atribuicao ao reutilizar.
A3: Resultados CSV | B3: matches.csv | C3: https://raw.githubusercontent.com/jfjelstul/worldcup/master/data-csv/matches.csv | D3: Fonte bruta baixada para resultados das Copas 2006-2022. | E3: Sem odds; dados historicos para uso academico.
A4: Cartoes CSV | B4: bookings.csv | C4: https://raw.githubusercontent.com/jfjelstul/worldcup/master/data-csv/bookings.csv | D4: Cartoes amarelos, vermelhos diretos, segundo amarelo e expulsao por partida/equipe. | E4: TotalCards do modelo usa amarelos + expulsoes, alinhado a HY+AY+HR+AR.
